<?xml version="1.0" encoding="UTF-8"?>
<testng-results ignored="2" total="3" passed="0" failed="1" skipped="0">
  <reporter-output>
  </reporter-output>
  <suite started-at="2022-03-25T07:35:13Z" name="Failed suite [Regression test Suite]" finished-at="2022-03-25T07:35:18Z" duration-ms="4735">
    <groups>
    </groups>
    <test started-at="2022-03-25T07:35:13Z" name="Demo Cart Test(failed)" finished-at="2022-03-25T07:35:18Z" duration-ms="4735">
      <class name="testngsessions.DemoCartAppTest">
        <test-method is-config="true" signature="setup()[pri:0, instance:testngsessions.DemoCartAppTest@7c469c48]" started-at="2022-03-25T07:35:13Z" name="setup" finished-at="2022-03-25T07:35:17Z" duration-ms="4459" status="PASS">
          <reporter-output>
          </reporter-output>
        </test-method> <!-- setup -->
        <test-method signature="urlTest()[pri:0, instance:testngsessions.DemoCartAppTest@7c469c48]" started-at="2022-03-25T07:35:17Z" name="urlTest" description=" urltest" finished-at="2022-03-25T07:35:17Z" duration-ms="14" status="FAIL">
          <exception class="java.lang.AssertionError">
            <message>
              <![CDATA[expected [true] but found [false]]]>
            </message>
            <full-stacktrace>
              <![CDATA[java.lang.AssertionError: expected [true] but found [false]
at org.testng.Assert.fail(Assert.java:96)
at org.testng.Assert.failNotEquals(Assert.java:776)
at org.testng.Assert.assertTrue(Assert.java:44)
at org.testng.Assert.assertTrue(Assert.java:54)
at testngsessions.DemoCartAppTest.urlTest(DemoCartAppTest.java:21)
at java.base/jdk.internal.reflect.NativeMethodAccessorImpl.invoke0(Native Method)
at java.base/jdk.internal.reflect.NativeMethodAccessorImpl.invoke(NativeMethodAccessorImpl.java:78)
at java.base/jdk.internal.reflect.DelegatingMethodAccessorImpl.invoke(DelegatingMethodAccessorImpl.java:43)
at java.base/java.lang.reflect.Method.invoke(Method.java:567)
at org.testng.internal.MethodInvocationHelper.invokeMethod(MethodInvocationHelper.java:124)
at org.testng.internal.Invoker.invokeMethod(Invoker.java:583)
at org.testng.internal.Invoker.invokeTestMethod(Invoker.java:719)
at org.testng.internal.Invoker.invokeTestMethods(Invoker.java:989)
at org.testng.internal.TestMethodWorker.invokeTestMethods(TestMethodWorker.java:125)
at org.testng.internal.TestMethodWorker.run(TestMethodWorker.java:109)
at org.testng.TestRunner.privateRun(TestRunner.java:648)
at org.testng.TestRunner.run(TestRunner.java:505)
at org.testng.SuiteRunner.runTest(SuiteRunner.java:455)
at org.testng.SuiteRunner.runSequentially(SuiteRunner.java:450)
at org.testng.SuiteRunner.privateRun(SuiteRunner.java:415)
at org.testng.SuiteRunner.run(SuiteRunner.java:364)
at org.testng.SuiteRunnerWorker.runSuite(SuiteRunnerWorker.java:52)
at org.testng.SuiteRunnerWorker.run(SuiteRunnerWorker.java:84)
at org.testng.TestNG.runSuitesSequentially(TestNG.java:1208)
at org.testng.TestNG.runSuitesLocally(TestNG.java:1137)
at org.testng.TestNG.runSuites(TestNG.java:1049)
at org.testng.TestNG.run(TestNG.java:1017)
at org.testng.remote.AbstractRemoteTestNG.run(AbstractRemoteTestNG.java:115)
at org.testng.remote.RemoteTestNG.initAndRun(RemoteTestNG.java:251)
at org.testng.remote.RemoteTestNG.main(RemoteTestNG.java:77)
]]>
            </full-stacktrace>
          </exception> <!-- java.lang.AssertionError -->
          <reporter-output>
          </reporter-output>
        </test-method> <!-- urlTest -->
        <test-method is-config="true" signature="tearDown()[pri:0, instance:testngsessions.DemoCartAppTest@7c469c48]" started-at="2022-03-25T07:35:17Z" name="tearDown" finished-at="2022-03-25T07:35:18Z" duration-ms="239" status="PASS">
          <reporter-output>
          </reporter-output>
        </test-method> <!-- tearDown -->
      </class> <!-- testngsessions.DemoCartAppTest -->
    </test> <!-- Demo Cart Test(failed) -->
  </suite> <!-- Failed suite [Regression test Suite] -->
</testng-results>
